Workbook

Sheet Overview
A4: System | B4: In-scope mean /21 | C4: Out-of-scope mean /15 | D4: Overall %
A5: System 1 v2 | B5: ='System 1 v2'!X27 -> 11 | C5: ='System 1 v2'!X28 -> 7.75 | D5: ='System 1 v2'!Y29 -> 0.52238095
A6: System 2 v2 | B6: ='System 2 v2'!X27 -> 14.25 | C6: ='System 2 v2'!X28 -> 10.5 | D6: ='System 2 v2'!Y29 -> 0.68285714
A7: System 3 v2 | B7: ='System 3 v2'!X27 -> 14.9375 | C7: ='System 3 v2'!X28 -> 11.25 | D7: ='System 3 v2'!Y29 -> 0.71904762
A8: System 4 v2 | B8: ='System 4 v2'!X27 -> 14.625 | C8: ='System 4 v2'!X28 -> 10.75 | D8: ='System 4 v2'!Y29 -> 0.70047619
A12: Multi-source & cross-topic synthesis | B12: Relevance | C12: Factual | D12: Grounding | E12: Synthesis | F12: Diversity | G12: Uncertainty | H12: Policy use
A13: System 1 v2 | B13: =AVERAGE('System 1 v2'!P6:P21) -> 1.875 | C13: =AVERAGE('System 1 v2'!Q6:Q21) -> 1.5625 | D13: =AVERAGE('System 1 v2'!R6:R21) -> 1.375 | E13: =AVERAGE('System 1 v2'!S6:S21) -> 1.375 | F13: =AVERAGE('System 1 v2'!T6:T21) -> 1.9375 | G13: =AVERAGE('System 1 v2'!U6:U21) -> 1.625 | H13: =AVERAGE('System 1 v2'!V6:V21) -> 1.25
A14: System 2 v2 | B14: =AVERAGE('System 2 v2'!P6:P21) -> 2 | C14: =AVERAGE('System 2 v2'!Q6:Q21) -> 2 | D14: =AVERAGE('System 2 v2'!R6:R21) -> 1.875 | E14: =AVERAGE('System 2 v2'!S6:S21) -> 1.9375 | F14: =AVERAGE('System 2 v2'!T6:T21) -> 2.5 | G14: =AVERAGE('System 2 v2'!U6:U21) -> 2.125 | H14: =AVERAGE('System 2 v2'!V6:V21) -> 1.8125
A15: System 3 v2 | B15: =AVERAGE('System 3 v2'!P6:P21) -> 2.75 | C15: =AVERAGE('System 3 v2'!Q6:Q21) -> 2 | D15: =AVERAGE('System 3 v2'!R6:R21) -> 1.875 | E15: =AVERAGE('System 3 v2'!S6:S21) -> 1.9375 | F15: =AVERAGE('System 3 v2'!T6:T21) -> 2.375 | G15: =AVERAGE('System 3 v2'!U6:U21) -> 2.1875 | H15: =AVERAGE('System 3 v2'!V6:V21) -> 1.8125
A16: System 4 v2 | B16: =AVERAGE('System 4 v2'!P6:P21) -> 2.0625 | C16: =AVERAGE('System 4 v2'!Q6:Q21) -> 1.9375 | D16: =AVERAGE('System 4 v2'!R6:R21) -> 1.8125 | E16: =AVERAGE('System 4 v2'!S6:S21) -> 2 | F16: =AVERAGE('System 4 v2'!T6:T21) -> 2.75 | G16: =AVERAGE('System 4 v2'!U6:U21) -> 2.1875 | H16: =AVERAGE('System 4 v2'!V6:V21) -> 1.875
A20: System | B20: Mean words | C20: Within 150 limit | D20: Mean seconds | E20: Total cost | F20: Fabricated citations | G20: average doc cited per answer
A21: System 1 v2 | B21: 320 | C21: 0/20 | D21: 30.9 | E21: free | F21: 6 | G21: 3.6
A22: System 2 v2 | B22: 180 | C22: 1/20 | D22: 2.1 | E22: $0.12 | F22: 0 | G22: 4.2
A23: System 3 v2 | B23: 143 | C23: 16/20 | D23: 35.1 | E23: $0.27 | F23: 0 | G23: 4.1
A24: System 4 v2 | B24: 184 | C24: 1/20 | D24: 6.6 | E24: $0.27 | F24: 0 | G24: 5.3

Sheet System 1 v2
A1: System 1 v2
F4: EXPECTED EVIDENCE | I4: WHAT THE SYSTEM DID | P4: SCORING
A5: Q ID | B5: Category | C5: Difficulty | D5: Topic area | E5: Question | F5: Expected corpus documents | G5: Expected uncertainty / disagreement | H5: Expected good behaviour | I5: Retrieved chunk IDs | J5: Invalid citations | K5: Words | L5: Seconds | M5: In tokens | N5: Out tokens | O5: Cost (USD) | P5: R | Q5: F | R5: G | S5: S | T5: D | U5: U | V5: P | W5: Out of | X5: Total | Y5: % | Z5: Scoring comments | AA5: Actual system output | AB5: Paid tokens | AC5: Audit run ID
A6: Q01 | B6: Direct evidence retrieval | C6: Easy | D6: Sources / emissions | E6: What are the main sources of atmospheric microplastics and which should be considered when considering emission-reduction policy interventions? | F6: DOC003,DOC002 DOC55DOC45 DOC52 DOC038 DOC05 DOC011 DOC29 | G6: Ther is some ambiguaty between parctile cizing as there is no stnadardised micropasitcs sizing method. They change with the method used and the testing envriomnet. | H6: should name the main sources and be clear where the coupus does or does not support prioritising them. Aswell as not giving a ranking as a ranking of the different methods is not given in the coupus. | I6: DOC046::chunk::29; DOC012::chunk::187; DOC052::chunk::33; DOC003::chunk::172; DOC108::chunk::284; DOC029::chunk::8 | J6: none | K6: 325 | L6: 41.396 | M6: 1871 | N6: 478 | O6: 0 | P6: 2 | Q6: 1 | R6: 2 | S6: 2 | T6: 2 | U6: 1 | V6: 1 | W6: 21 | X6: =IF(COUNT(P6:V6)=0,"",SUM(P6:V6)) -> 11 | Y6: =IF(X6="","",X6/21) -> 0.52380952 | Z6: Its listes the souces but dosnt what what is most imporntat as well as treading an india specifc findings as global | AA6: The main sources of atmospheric microplastics include plastic use, industrial activities, consumer products, and human activities, which release plastic particles into the atmosphere through various pathways (DOC052::chunk::33, DOC046::chunk::29). These sources can be categorized into primary and secondary sources. Primary sources directly release plastic particles into the atmosphere, such as emissions from textiles, resuspension from traffic, urban dust, and industrial activities (DOC052::chunk::33, DOC046::chunk::29). Secondary sources, on the other hand, are the products of the degradation of larger plastics in the atmosphere, such as nanoplastics (DOC046::chunk::29). The presence of atmospheric microplastics contributes to atmospheric particulate matter and can be inhaled, deposited onto land and water surfaces, or redistributed across environmental compartments (DOC052::chunk::33). The sources of nanoplastics are similar to those of microplastics, with primary nanoplastics being produced intentionally and secondary nanoplastics being the products of the degradation of larger plastics in the atmosphere (DOC046::chunk::29). When considering emission-reduction policy interventions, it is essential to identify the sources of atmospheric microplastics and their relative contributions to the total concentration of microplastics in the air (DOC003::chunk::172). The shipping and transportation industries, wind erosion from landfill, dried landfill leachate, entrainment from waste compaction, and wind abrasion of plastic-rich biosolid applied to agricultural land are potential emission sources of microplastics into the air (DOC003::chunk::172). Policy interventions should focus on mitigating the leakage of microplastics, and further research is necessary to evaluate the cost-effectiveness of possible mitigation options and inform the choice of policy interventions (DOC108::chunk::284). Significant progress can be achieved in the short term by focusing on mitigation options that generate co-benefits aligned with other environmental policy objectives, such as policies for climate change mitigation and improvements in air quality and water quality (DOC108::chunk::284). In conclusion, the main sources of atmospheric microplastics include plastic use, industrial activities, consumer products, and human activities, and policy interventions should focus on mitigating the leakage of microplastics. Further research is necessary to evaluate the cost-effectiveness of possible mitigation options and inform the choice of policy interventions. | AB6: 0 (local model) | AC6: c427cfaf-98ee-4f2d-b638-b55b6db5398c
A7: Q02 | B7: Direct evidence retrieval | C7: Easy | D7: Measurement / monitoring | E7: What measurement approaches are used for atmospheric microplastics, and what are the implications for policy design? | F7: DOC109 DOC 030DOC111 DOC095 DOC017 | G7: Lack of standardisation, differing size thresholds and montering systesm so the answer should considers this when comparing diffent aproaches . | H7: Should separate identifcation and collection sections and desigus the comparitbilty between studies and the fact that is is limited and ther is no standised montering system in the courpus | I7: DOC030::chunk::2; DOC078::chunk::271; DOC014::chunk::179; DOC041::chunk::32; DOC078::chunk::232; DOC095::chunk::63 | J7: none | K7: 378 | L7: 36.349 | M7: 1960 | N7: 532 | O7: 0 | P7: 1 | Q7: 2 | R7: 2 | S7: 1 | T7: 3 | U7: 1 | V7: 1 | W7: 21 | X7: =IF(COUNT(P7:V7)=0,"",SUM(P7:V7)) -> 11 | Y7: =IF(X7="","",X7/21) -> 0.52380952 | Z7: The output explain how the sames are collected but dosnt show or explane how the plsacics are idnitigied . | AA7: The measurement of atmospheric microplastics is a complex task, and various approaches have been employed to quantify their presence in the air. According to [DOC041::chunk::32], several studies have used passive collection methods, such as in the studies conducted by Allen et al. (2019) and Cai et al. (2017), while others have employed active collection methods, including rain samplers, fallout collectors, and particulate samplers [DOC041::chunk::32]. The particulate or pump samplers have been particularly useful in quantifying the concentration of atmospheric microplastics, especially particles that are immediately suspended [DOC041::chunk::32]. The size of atmospheric microplastics also varies, with fibres typically ranging from 100 to 500 μm, and fragments concentrated in the range of <100 μm [DOC095::chunk::63]. This information is crucial for policy design, as it highlights the need for targeted interventions to mitigate the impact of microplastics on the environment. In terms of policy implications, the measurement of atmospheric microplastics can inform the design of effective policies to reduce microplastic pollution. For instance, the use of extended producer responsibility (EPR) can encourage manufacturers to design more sustainable packaging and products [DOC078::chunk::232]. Additionally, the development of metrics and measurement techniques to assess the macroeconomic benefits of increased resource productivity can help policymakers evaluate the effectiveness of interventions and make informed decisions [DOC078::chunk::232]. However, there are still significant gaps in our understanding of atmospheric microplastics, particularly in terms of their sources, sinks, and fluxes [DOC030::chunk::2]. Further research is needed to develop more accurate models for estimating the fluxes of atmospheric microplastic emission, transport, and deposition [DOC030::chunk::2]. This will enable policymakers to make more informed decisions and design more effective policies to mitigate the impact of microplastics on the environment. In terms of behavioral research, understanding the motivations behind specific behaviors can highlight novel pathways to change [DOC014::chunk::179]. For example, some people may avoid plastic packaging due to health concerns about additives, which can inform the design of interventions to change behavior [DOC014::chunk::179]. This information can be used to design more effective policies to reduce microplastic pollution. Overall, the measurement of atmospheric microplastics is a complex task that requires a multidisciplinary approach. By understanding the various measurement approaches and the implications for policy design, policymakers can make more informed decisions and design more effective policies to mitigate the impact of microplastics on the environment. | AB7: 0 (local model) | AC7: e2325534-afb9-415c-992e-93004fff86c8
A8: Q03 | B8: Direct evidence retrieval | C8: Medium | D8: Transport / deposition | E8: What is the evidence for atmospheric transport and deposition of microplastics, and what does this imply for considering long-term pollution? | F8: DOC058 DOc035 DOc005 DOc023 DOC091 | G8: magnitues are not well established as well as estimate range by upto 4 orders of manigitue DOC059: "no one has yet published a comprehensive size distribution for microplastics smaller than 10 µm" | H8: seperates the quantitive findings from the qualittive ones and make refercne th oth range in orders of mangitude. And that the deposisition estiamtes are demandands on the models used | I8: DOC002::chunk::71; DOC014::chunk::223; DOC016::chunk::212; DOC095::chunk::78; DOC059::chunk::107; DOC106::chunk::137 | J8: DOC024::chunk::24; DOC026::chunk::26; DOC027::chunk::27; DOC029::chunk::29 | K8: 347 | L8: 35.378 | M8: 2503 | N8: 495 | O8: 0 | P8: 2 | Q8: 1 | R8: 0 | S8: 1 | T8: 2 | U8: 1 | V8: 1 | W8: 21 | X8: =IF(COUNT(P8:V8)=0,"",SUM(P8:V8)) -> 8 | Y8: =IF(X8="","",X8/21) -> 0.38095238 | Z8: Four of the citations were fabircated . | AA8: The scientific evidence suggests that atmospheric transport is a significant pathway for microplastics to reach remote regions [DOC002::chunk::71]. Studies have demonstrated the presence of microplastics in the atmosphere, including in remote mountain catchments [DOC024::chunk::24] and in the free troposphere [DOC026::chunk::26]. Microplastics have been detected in the Arctic region, where they can be transported through the cryosphere [DOC027::chunk::27]. The atmospheric transport of microplastics can lead to their deposition in various environments, including oceans and land surfaces [DOC029::chunk::29]. The abundance and characteristics of atmospheric microplastics vary widely across different regions, with fibres and fragments being the most frequently identified shapes [DOC095::chunk::78]. The size distribution of atmospheric microplastics is difficult to determine due to differences in targeted particle size [DOC095::chunk::78]. Wind, snowfall, and weathering play important roles in the transport and deposition of atmospheric microplastics [DOC095::chunk::78]. The evidence suggests that atmospheric microplastics can be transported long distances and deposited in remote areas, potentially influencing locations far from microplastic pollution sources [DOC095::chunk::78]. However, current research on atmospheric microplastics is in its early stages, and there is a need for more comparable data on abundance and characterization, particularly in remote areas [DOC095::chunk::78]. In terms of policy implications, the evidence suggests that atmospheric transport and deposition of microplastics should be considered when developing long-term pollution strategies. The WHO guidelines for air quality suggest that long-term exposure to air pollutants can have significant health effects, and similar considerations may apply to microplastics [DOC106::chunk::137]. However, the evidence on the health effects of microplastics is still limited, and more research is needed to fully understand the risks associated with atmospheric microplastic pollution. It is essential to note that the evidence on the health effects of microplastics is still emerging, and more research is needed to fully understand the risks associated with atmospheric microplastic pollution. The WHO guidelines for air quality suggest that long-term exposure to air pollutants can have significant health effects, and similar considerations may apply to microplastics. However, the evidence on the health effects of microplastics is still limited, and more research is needed to fully understand the risks associated with atmospheric microplastic pollution. | AB8: 0 (local model) | AC8: 360e2be6-9f1f-4ff3-a9e6-edb124f42bd2
A9: Q04 | B9: Direct evidence retrieval | C9: Medium | D9: Human health / exposure | E9: What evidence is there about human exposure to atmospheric microplastics, and what are the main limitations policymakers should be aware of? | F9: DOC017,DOC018 Doc 021(inhillantion) DOC046,DOC025,D0c043 (toxicoligy), DOC014 (evidance review). DOC063(microplasics in lung tissue). DOC0112,Doc113 (Uk indoor expsoure menasurments | G9: that there is insufficnet evdiance to acess the helth risks and there isnt an indefited relationships between quantities and health affects\. Exposure is given but harm isnt. That toxicoluge is on cells no peope. And could be work place realted not atmophere wedont know | H9: give clear evidance shoes there isnt a defined risk acessment to carry out and dsont convernt findings on animlas in human findings. as well as giving a good policy maker overview. | I9: DOC014::chunk::239; DOC095::chunk::74; DOC014::chunk::241; DOC033::chunk::2; DOC093::chunk::4; DOC035::chunk::6 | J9: none | K9: 243 | L9: 24.705 | M9: 2088 | N9: 345 | O9: 0 | P9: 2 | Q9: 2 | R9: 1 | S9: 1 | T9: 2 | U9: 1 | V9: 1 | W9: 21 | X9: =IF(COUNT(P9:V9)=0,"",SUM(P9:V9)) -> 10 | Y9: =IF(X9="","",X9/21) -> 0.47619048 | Z9: Accurate, but one claim comes from on a keyword list. Confuses exposure with harm. | AA9: There is evidence to suggest that human exposure to atmospheric microplastics is a concern. Studies have shown that microplastics can be ingested by different types of organisms, including species widely used in the human diet [DOC095::chunk::74]. Additionally, microplastic particles have been found in human lungs, including excised lung cancers and lung biopsies [DOC095::chunk::74]. The presence of microplastics in the atmosphere has been linked to adverse respiratory and cardiovascular effects [DOC095::chunk::74]. Furthermore, research has shown that synthetic textiles are a main source of airborne microplastics, and fibers are the dominant shape of microplastics in the atmosphere [DOC033::chunk::2]. However, there are limitations to the current evidence. The studies on human exposure to atmospheric microplastics are limited, and more research is needed to fully understand the risks [DOC033::chunk::2]. Additionally, the methods used to measure and assess microplastic concentrations and exposure are not yet harmonized, which can lead to inconsistencies in the data [DOC014::chunk::241]. Furthermore, the ecological and human health risks of microplastics are still not well understood, and more research is needed to clarify the effects of microplastic exposure on biota and humans [DOC014::chunk::241]. Policymakers should be aware that the current evidence suggests that human exposure to atmospheric microplastics is a concern, but more research is needed to fully understand the risks. The main limitations of the current evidence are the limited number of studies, the lack of harmonization of methods, and the need for more research on the ecological and human health risks of microplastics. | AB9: 0 (local model) | AC9: 40805678-ed9d-4bcd-a8dd-d9421db2b895
A10: Q05 | B10: Multi-source & cross-topic synthesis | C10: Medium | D10: Sources + transport | E10: What does the evidence suggest about interventions regarding the source-to-deposition pathway? | F10: DOC003,005,002 (sources of microplassitcs and the atomphere cycle) DOC034,058,029 (transport). DOC073,065,073(what the uk and eu is curnety doing DOc022, 108 (interviention modeling ) | G10: none of the papers actually rank the interventions they just give solutions as there is no review in the coupus, thre are different orders of mannuture in the transport sections so this needs to be comunicated clearly | H10: shows clearnly the different stages as well as keeping clear and traspanrtry to the souces. Keeping the actualy evideance of wahts going on sepreatate from the findings about possible interventions. Showuldn show where to intervene and diffent oiptions but not suggest a best option | I10: DOC014::chunk::240; DOC091::chunk::37; DOC014::chunk::49; DOC105::chunk::52; DOC038::chunk::77; DOC029::chunk::33 | J10: none | K10: 312 | L10: 29.247 | M10: 1901 | N10: 450 | O10: 0 | P10: 1 | Q10: 1 | R10: 1 | S10: 1 | T10: 2 | U10: 1 | V10: 1 | W10: 21 | X10: =IF(COUNT(P10:V10)=0,"",SUM(P10:V10)) -> 8 | Y10: =IF(X10="","",X10/21) -> 0.38095238 | Z10: Suggests sewage treatment, which is about water not air. As wella s criding a paper it hasn’t seen. | AA10: The evidence suggests that atmospheric microplastics are a significant concern, with studies showing that they can be transported and deposited in both urban and pristine tropical locations, including remote islands (DOC091::chunk::37). This highlights the need for a comprehensive understanding of the source-to-deposition pathway. Research has identified various sources of microplastics, including atmospheric deposition, sewage treatment plants, and export from rivers (DOC014::chunk::49). However, the relative importance of these sources varies, with synthetic polymers from car tires and plastic-based textiles being major contributors (Siegfried et al., 2017). The transportation of microplastics in the atmosphere is a complex process, driven by dispersion, transportation, and deposition mechanisms (DOC038::chunk::77). While there is a scarcity of information on the processes assisting MPs transport in the atmosphere, back-trajectory analysis and modeling can provide insights into the source locations and transport pathways (Akhbarizadeh et al., 2021; Allen et al., 2019). The physical characteristics of microplastic particles, such as shape and morphology, can influence their transport and deposition (DOC029::chunk::33). However, the assumption that microplastics found in remote samples are primarily composed of MPs from the nearest area of heavy anthropogenic activity may not be accurate, as atmospheric deposition can carry MPs thousands of kilometers from their source. In terms of interventions, the evidence suggests that addressing the source-to-deposition pathway requires a multi-faceted approach. This could include: * Improving sewage treatment infrastructure to reduce microplastic emissions (Mintenig et al., 2017) * Implementing policies to reduce the use of synthetic polymers and plastic-based textiles (Siegfried et al., 2017) * Developing more effective methods for tracking and tracing microplastic sources and transport pathways (Allen et al., 2019) * Enhancing our understanding of the physical characteristics of microplastic particles and their influence on transport and deposition (DOC029::chunk::33) However, it is essential to note that the current scientific evidence is limited, and further research is needed to fully understand the source-to-deposition pathway and develop effective interventions. | AB10: 0 (local model) | AC10: e65f8b22-6c31-4aeb-933b-22bf6958a6e0
A11: Q06 | B11: Multi-source & cross-topic synthesis | C11: Hard | D11: Exposure + human health | E11: What does the current evidence on atmospheric microplastics suggest in terms of the human health impacts, and its relevance for policy consideration? | F11: DOC017, 018 (Committee on the Medical Effects of Air Pollutants ). DOC021(inhilantion). DOC014(Science Advice for Policy by European Academies review) DOC045, 025, 043 (toxicoligy) DOC063 ( Micorpstics in lungs) DOC0112,113 (Uk indoor expsoure menasurments | G11: comeap finds insufficne evidance to acess the health risks as there is no dose relatships. As well as Sepea finds no evidance of widespready risk however its from 2019 outdie courpus range | H11: give clear evidance shoes there isnt a defined risk acessment to carry out and dsont convernt findings on animlas in human findings. as well as giving a good policy maker overview. | I11: DOC014::chunk::239; DOC095::chunk::74; DOC052::chunk::12; DOC095::chunk::9; DOC017::chunk::17; DOC093::chunk::4 | J11: none | K11: 390 | L11: 33.083 | M11: 1856 | N11: 528 | O11: 0 | P11: 2 | Q11: 1 | R11: 0 | S11: 1 | T11: 1 | U11: 2 | V11: 1 | W11: 21 | X11: =IF(COUNT(P11:V11)=0,"",SUM(P11:V11)) -> 8 | Y11: =IF(X11="","",X11/21) -> 0.38095238 | Z11: Nine extrenal references only one from the corpus. Found the key UK report and ignored it. | AA11: The current evidence on atmospheric microplastics suggests that they can be ingested by organisms, including those used in the human diet [DOC095::chunk::74]. Microplastics have been found in the environment, and their presence has been linked to adverse respiratory and cardiovascular effects [Churg and Brauer, 2000]. Although the visually observed microplastic fibres are supposedly too large to be inhaled, there is an exposure may occur through dust ingestion, particularly for young children [Dris et al., 2017; Wright and Kelly, 2017]. Previous studies have identified cellulosic and plastic fibres in human lungs [Pauly et al., 1998; Wright and Kelly, 2017], and for workers in plastic processing factories to demonstrate breathing and health problems [Kremer et al., 1994]. The toxicological evidence suggests that there is some limited evidence from toxicity studies to suggest that NMPs deposited in the lung induce oxidative stress, inflammation, and cytotoxicity [WHO, 2022]. However, the uncertainty in the data for exposure to biologically relevant NMPs is a significant barrier to assessing the hazard to human health [WHO, 2022]. The dose of particles needed to elicit an adverse effect and the corresponding toxicological end points will be dependent on a combination of factors, including the physical and chemical properties of the NMPs. The current evidence on atmospheric microplastics suggests that they have human health implications at very high concentrations [Prata, 2018]. The risk of microplastic inhalation could be exacerbated by their ability to carry toxic pollutants from land surfaces [Borthakur et al., 2021]. Therefore, it is critical to develop rapid monitoring systems to assess the atmospheric deposition of microplastics in urban areas. In terms of policy consideration, the current evidence suggests that there is a need for a systematic overview on policy options and their predicted efficiency and relevance to reduce current and future risks of NMP [SAM, 2018]. A recent WHO report [WHO, 2022] concluded that there is some limited evidence from toxicity studies to suggest that NMPs deposited in the lung induce oxidative stress, inflammation, and cytotoxicity. However, the report also stated that the uncertainty in the data for exposure to biologically relevant NMPs is a significant barrier to assessing the hazard to human health. Overall, the current evidence on atmospheric microplastics suggests that they have human health implications and that there is a need for further research and policy consideration to reduce the risks associated with NMPs. | AB11: 0 (local model) | AC11: 5c4c2b09-65e7-4fb1-b5fa-7f9608cfcc38
A12: Q07 | B12: Multi-source & cross-topic synthesis | C12: Hard | D12: Deposition + ecology | E12: How does atmospheric deposition cause atmospheric microplastics to reach ecosystems, and what remains uncertain? | F12: DOC027 ( desposition to wetlands) DOC049 (ecoligcal risks) DOC103, 104, 026 ( soil and plants) DOC105 (unknown aspects of plastic pollution) DOC050 , 062 (deposistion measruments) | G12: the coupus mainly focuses on deposisiton there isnt much evidance about the impact of this deposiston of microplastics on ecosystems | H12: must speerate the effects form the effects evidance . And must note that the concetations used in the lab soil expements is much higher than that was ovserved in the field.. | I12: DOC027::chunk::4; DOC095::chunk::69; DOC005::chunk::5; DOC014::chunk::110; DOC053::chunk::24; DOC027::chunk::6 | J12: none | K12: 345 | L12: 32.78 | M12: 1937 | N12: 511 | O12: 0 | P12: 2 | Q12: 2 | R12: 2 | S12: 2 | T12: 2 | U12: 2 | V12: 2 | W12: 21 | X12: =IF(COUNT(P12:V12)=0,"",SUM(P12:V12)) -> 14 | Y12: =IF(X12="","",X12/21) -> 0.66666667 | Z12: BFigures correct and honest about the gaps. | AA12: Atmospheric deposition is a significant source of microplastic pollution in various aquatic ecosystems, with studies suggesting that it contributes more microplastics to oceans than inland river inputs [DOC027::chunk::4]. Microplastics can be transported through the atmosphere via wind, snowfall, and rainfall, reaching remote areas without local sources of plastics [DOC095::chunk::69]. The atmospheric transport of microplastics can be influenced by various factors, including plastic production and usage, which has been documented by ombrotrophic peat cores [Allen et al., 2021]. The deposition rate of microplastics in the atmosphere has been estimated to range from 50 to 700 plastics m−2 · d−1, with some 22 Gg (22,000 tons) of microplastic potentially deposited across the contiguous United States each year [DOC005::chunk::5]. However, the mechanisms governing microplastic transport in the atmosphere remain poorly understood [DOC053::chunk::24]. It is unclear how plastics are emitted to the atmosphere, with some research suggesting that coarse mode particles (>2.5 μm) are typically entrained into the atmosphere through mechanical processes, such as dust entrainment during strong wind events or wind or wave breaking of sea surface spray [DOC005::chunk::5]. The interactions between atmospheric microplastics and ecosystems are complex, with microplastics accumulating in various environmental compartments, including the hydrosphere, pedosphere, and atmosphere [DOC053::chunk::24]. The effects of atmospheric microplastics on ecosystems are still largely unknown, with some research suggesting that they can contribute to habitat degradation and pose ecological and health risks to biota and humans [DOC053::chunk::24]. What remains uncertain is the extent to which aerial pathways contribute to microplastic input and how socio-environmental factors influence this contribution [DOC027::chunk::6]. Additionally, the mechanisms governing microplastic transport in the atmosphere, particularly in the pedosphere and atmosphere, remain poorly understood [DOC053::chunk::24]. Further research is needed to better understand the complex interactions between atmospheric microplastics and ecosystems. Scientific evidence suggests that atmospheric deposition is a significant source of microplastic pollution in various aquatic ecosystems, with microplastics being transported through the atmosphere via wind, snowfall, and rainfall. However, the mechanisms governing microplastic transport in the atmosphere remain poorly understood, and further research is needed to better understand the complex interactions between atmospheric microplastics and ecosystems. | AB12: 0 (local model) | AC12: da96e98f-2664-436e-a5e6-a9404ce72c3f
A13: Q08 | B13: Multi-source & cross-topic synthesis | C13: Hard | D13: Measurement + evidence interpretation | E13: How do differences in sampling and methods affect comparison of atmospheric microplastic evidence to inform policy? | F13: DOC109(chemical anlyais) DOC030 ( anlyalitcal methods) DOC111(anlyasis of deposition) DOC095(standarisation gaps) DOC017(Commitee of the medical effects of air polutants) DOC090, 061, 064 (sampling studies) | G13: there is no standissed method and comparitson is dificulrt as there is deiiffernt collection,processing andn alyltical methods across all of the studies | H13: explain the diffrenty methods, and not compairing figures from from the studdies directly as they are from diffent tecniques and there is no standised method and dosent recommend a montering method/ standards that’s not in the coupus. | I13: DOC033::chunk::31; DOC030::chunk::43; DOC003::chunk::7; DOC021::chunk::86; DOC006::chunk::15; DOC095::chunk::79 | J13: none | K13: 335 | L13: 28.435 | M13: 1517 | N13: 469 | O13: 0 | P13: 2 | Q13: 2 | R13: 2 | S13: 2 | T13: 3 | U13: 2 | V13: 2 | W13: 21 | X13: =IF(COUNT(P13:V13)=0,"",SUM(P13:V13)) -> 15 | Y13: =IF(X13="","",X13/21) -> 0.71428571 | Z13: balmes the lacks of standard method. All citations check out. | AA13: The current understanding of atmospheric microplastics is limited due to the lack of standardized sampling and measurement methods [DOC033::chunk::31]. Studies have reported varying results due to differences in sampling techniques, analytical methods, and polymers investigated [DOC003::chunk::7]. This inconsistency hinders comparability and makes it challenging to establish a comprehensive understanding of atmospheric microplastics [DOC030::chunk::43]. The use of different sampling methods, such as passive and active sampling, can collect different types of microplastics, affecting empirical values like concentration levels [DOC006::chunk::15]. Passive sampling methods, which are commonly used, can collect a wide range of particle sizes but may be affected by adverse weather conditions [DOC006::chunk::15]. The lack of standardized methods and inconsistent units in reporting results prevent comparison of studies and extrapolation of data [DOC021::chunk::86]. This limitation is further exacerbated by the differences in sampling methods and the reporting of results, making it difficult to establish a clear understanding of the sources, prevalence, and behavior of atmospheric microplastics [DOC003::chunk::7]. To address these limitations, it is essential to establish standardized methods for sampling and measurement of atmospheric microplastics [DOC095::chunk::79]. This will enable reproducibility and comparability of results, allowing for the quality data necessary to conduct risk assessments. Further research is needed to better understand the interaction between atmospheric microplastics and other chemicals, ecosystems, and human exposure. Scientific evidence suggests that atmospheric microplastics are a potentially important source of exposure, with implications for human health [DOC021::chunk::86]. However, the effects of inhalation and ingestion of microplastics on human health are not well documented, and further research is needed to develop prevention and treatment measures [DOC033::chunk::31]. Possible policy implications: * Establishing standardized methods for sampling and measurement of atmospheric microplastics to ensure reproducibility and comparability of results. * Conducting further research to better understand the interaction between atmospheric microplastics and other chemicals, ecosystems, and human exposure. * Developing prevention and treatment measures to mitigate the potential health effects of atmospheric microplastic exposure. Note: The above answer is based solely on the provided sources and does not include any external information or recommendations. | AB13: 0 (local model) | AC13: 4bafd23b-5411-4b53-b493-8a3f39ff67a6
A14: Q09 | B14: Conflicting evidence & comparison | C14: Medium | D14: Measurement / monitoring | E14: How much do reported concentrations of atmospheric microplastics differ between environments and why? | F14: DOC095 (spread) DOC090 (weser,germany cathcment) DOC061, 113 (humber UK Indoors and Outdoors) DOC112, (Birmingham Indoor air) DOC041, 051 (forest urban rural) DOC030, 109 ( Explain variation) | G14: much of the information in the coupus on this topic is mearly methodoligy and some of the reptored concentrations differ by upto a thousnad times. And the spectromatry and mass spectromatry results and not comparible as one gives how many the other how much. and spectornomy hasa. floor in hte sizes it can detect of around 10um as anyhting below this is not noticeable in most studies. | H14: Reoports a rang of different reuslts and making sure to state the differnces in methods as well as sepesrating the differances caused by the diffrent envroments from the differances in methods | I14: DOC095::chunk::41; DOC003::chunk::81; DOC095::chunk::63; DOC003::chunk::62; DOC024::chunk::17; DOC053::chunk::37 | J14: none | K14: 213 | L14: 24.114 | M14: 2082 | N14: 332 | O14: 0 | P14: 2 | Q14: 1 | R14: 1 | S14: 1 | T14: 2 | U14: 0 | V14: 1 | W14: 21 | X14: =IF(COUNT(P14:V14)=0,"",SUM(P14:V14)) -> 8 | Y14: =IF(X14="","",X14/21) -> 0.38095238 | Z14: uses the wrong units and reports a concentration as a particle size. | AA14: The reported concentrations of atmospheric microplastics differ significantly between indoor and outdoor environments. According to Dris et al. (2017) and Gaston et al. (2020b), indoor concentrations are 6-6.5 times higher than outdoor concentrations [DOC003::chunk::81]. This discrepancy is likely due to the presence of indoor-generating sources, such as microplastics in dust and air conditioning systems [DOC053::chunk::37]. In contrast, outdoor concentrations are influenced by proximity to industrial zones, urban areas, and other sources of microplastic pollution [DOC053::chunk::37]. Within indoor environments, microplastic concentrations can vary depending on factors such as occupant lifestyle and location [DOC053::chunk::37]. In contrast, outdoor concentrations tend to be more consistent, with higher concentrations found near industrial zones and lower concentrations found over the open ocean [DOC003::chunk::62]. The size and shape of microplastics also differ between indoor and outdoor environments. Fibres and fragments are the most common shapes observed in both environments, but the size range is generally smaller in outdoor air, with 50-80% of fibres falling within the 100-500 μm range [DOC095::chunk::63]. In contrast, indoor microplastics tend to be larger, with a median size of 26,800 mg kg-1 [DOC095::chunk::41]. Overall, the reported concentrations of atmospheric microplastics differ significantly between indoor and outdoor environments, reflecting the complex interplay of sources, sinks, and transport mechanisms that govern the distribution of microplastics in the atmosphere. | AB14: 0 (local model) | AC14: 7fb3507f-b2e6-4d68-b0d1-70a2e94e6b29
A15: Q10 | B15: Conflicting evidence & comparison | C15: Hard | D15: Sources / intervention relevance | E15: How consistent is the evidence that tyre wear is a major source of atmospheric microplastics, and how reliable are current estimates of its contribution to the problem? | F15: DOC003, 109 (cover tyre wear) DOC005 (Emission figures) DOC034, 047, 038, 045 ( reviews that mention tyrewear) DOC022 (estimates tyre loss from trafic data) | G15: the estimates dissagreee with DOc003 saying 84% of airmbone plastics come from road use. Howevern doc 005 says 96Gg of micro plastics aare entering long range transport from tyres. But them DOC0109 notes that tyres are only 40-60% poylomer so what dos actually count as a micro plastic nedes to be considerd | H15: tyre ware needs to be mentiond as one of the major couases of atmopeheric micro plastics but that the soruces give confliction results int terms of estimates. | I15: DOC038::chunk::28; DOC035::chunk::33; DOC003::chunk::45; DOC077::chunk::79; DOC038::chunk::26; DOC022::chunk::131 | J15: none | K15: 327 | L15: 30.397 | M15: 2307 | N15: 431 | O15: 0 | P15: 2 | Q15: 2 | R15: 0 | S15: 2 | T15: 0 | U15: 2 | V15: 1 | W15: 21 | X15: =IF(COUNT(P15:V15)=0,"",SUM(P15:V15)) -> 9 | Y15: =IF(X15="","",X15/21) -> 0.42857143 | Z15: no corpus citations at all, every number is an outside reference so none of it can be traced back. the estimates dont agree either, they range from 5-10% up to 30%. | AA15: The evidence suggests that tyre wear is a significant source of atmospheric microplastics. Studies have consistently shown that tyre wear particles can become airborne and contribute to microplastic pollution in the atmosphere. According to Kole et al. (2017), 0.1-10% of generated tyre wear and tear particles become airborne, while Evangeliou et al. (2020) estimated that 2907 k tonnes of microplastics in tyre wear per annum could be aerosolised globally. The Clean Air Strategy 2019 also acknowledges the importance of tyre wear as a source of microplastic pollution, investing £200,000 in research to improve understanding of the issue. However, there is some variation in estimates of the contribution of tyre wear to atmospheric microplastic pollution. Kole et al. (2017) reported that 5-10% of ocean MPs are tyre wear and tear, while Panko et al. (2013) and Kooi et al. (2018) ascribed 28% and 30% respectively to tyre wear and tear. The Global Plastics Outlook also notes that while tyre wear is a significant source of aerial microplastic pollution, brakes are responsible for a larger share of fine particulate matter (PM2.5). The reliability of current estimates is uncertain due to the limited number of studies on the topic and the variability in estimates. The Global Plastics Outlook notes that while the majority of microplastic emissions tends to remain close to their source, some particles can travel long distances, depending on location and atmospheric conditions. This highlights the need for further research to improve understanding of the issue. In terms of policy implications, the evidence suggests that tyre wear is a significant source of atmospheric microplastic pollution, and that reducing emissions from this source could be an effective way to mitigate the problem. The Clean Air Strategy 2019's investment in research to improve understanding of the issue is a positive step in this direction. However, further research is needed to provide more accurate estimates of the contribution of tyre wear to atmospheric microplastic pollution and to inform effective policy responses. | AB15: 0 (local model) | AC15: cbea2dd8-d0ee-496d-8a7e-1c628500f565
A16: Q11 | B16: Conflicting evidence & comparison | C16: Hard | D16: Transport / spatial scale | E16: What is agreed and what is disputed in the long-range transport of atmospheric microplastics, and how do transport estimates disagree in terms of scale? | F16: DOC058 (long term transport) DOC034 (remote region transport DOC005 (uncertantcys for transport and deposisiton) DOC029 (trasport in asia) DOC059 (atmopshertic Modeling) DOC095, 047 (Reviews) | G16: it is genrally agreed that trasport does occour to remote regions. But the sale is not this needs to be reflected in the answer | H16: it needs to show that trasport does occour even to remote rgions and make it clear that there is no definitive view on the scale. | I16: DOC005::chunk::21; DOC047::chunk::23; DOC058::chunk::0; DOC014::chunk::53; DOC035::chunk::34; DOC014::chunk::54 | J16: none | K16: 414 | L16: 38.859 | M16: 1983 | N16: 622 | O16: 0 | P16: 2 | Q16: 2 | R16: 2 | S16: 2 | T16: 2 | U16: 3 | V16: 2 | W16: 21 | X16: =IF(COUNT(P16:V16)=0,"",SUM(P16:V16)) -> 15 | Y16: =IF(X16="","",X16/21) -> 0.71428571 | Z16: Separates agreed from disputed but there is One stray reference. | AA16: The long-range transport of atmospheric microplastics is a complex and multifaceted issue, with various studies providing differing estimates and insights. One area of agreement is that microplastics can be transported over long distances through the atmosphere, with studies suggesting that they can travel across hemispheres (DOC058::chunk::0). However, the scale of this transport is disputed, with estimates ranging from 96 Gg · y<sup>−1</sup> (DOC005::chunk::21) to 284 Gg · y<sup>−1</sup> (36). The transport of microplastics through the atmosphere is influenced by various factors, including size, morphology, and meteorological conditions. Studies have shown that smaller microplastics, such as fibers, are transported more efficiently than larger fragments (DOC058::chunk::0). However, the role of meteorological parameters in remote locations is still unclear, with some studies suggesting that they may be less important than local sources (DOC035::chunk::34). The transport of microplastics through the atmosphere is also influenced by the presence of biota, with some studies suggesting that biota may drive substantial mass flows (DOC014::chunk::54). However, the role of ingestion-migration-egestion in the plastic debris budget is still unknown. In terms of scale, the estimates of microplastic transport through the atmosphere vary widely. Some studies suggest that microplastics can travel up to 95 km (DOC035::chunk::34), while others estimate that they can travel across hemispheres (DOC058::chunk::0). The lack of significant correlations with meteorological variables in some studies suggests that local sources may have a greater influence on microplastic deposition in central London (DOC035::chunk::34). Overall, the long-range transport of atmospheric microplastics is a complex and multifaceted issue, with various studies providing differing estimates and insights. Further research is needed to better understand the scale and mechanisms of this transport. Scientific evidence: * Microplastics can be transported over long distances through the atmosphere (DOC058::chunk::0). * The transport of microplastics through the atmosphere is influenced by various factors, including size, morphology, and meteorological conditions (DOC058::chunk::0, DOC035::chunk::34). * Smaller microplastics, such as fibers, are transported more efficiently than larger fragments (DOC058::chunk::0). * The role of biota in mass transport of microplastics is still unknown (DOC014::chunk::54). Possible policy implications: * Further research is needed to better understand the scale and mechanisms of microplastic transport through the atmosphere. * Local sources may have a greater influence on microplastic deposition in central London, suggesting that local regulations may be necessary. * The role of biota in mass transport of microplastics highlights the need for further research into the environmental fate of microplastics. Note: The above answer is based on the provided sources and does not include any additional information or assumptions. | AB16: 0 (local model) | AC16: 0f8e35b5-9805-4d25-b71b-be96032c51ed
A17: Q12 | B17: Conflicting evidence & comparison | C17: Hard | D17: UK relivance | E17: What existing UK policy instruments address microplastics, and do any of them cover atmospheric sources? | F17: DOC075 (packaging tax) DOC073 (Single Use bans) DOC072 (Microbeads) DOC084 Producer responcibilty) DOC078 (Air quality stratagy) DOC089 (Clean air zones) DOC077, 078, 082,088 (curnet uk strategys) | G17: there is a clear gap as ther is nothing in the coupus that links atmopsheric. As it does not fall under the efford to regualte particualte matter but ithis is mainly focused on pm 2.5 | H17: indentifyes a clear gap in the lesgisaltion | I17: DOC020::chunk::445; DOC035::chunk::2; DOC014::chunk::240; DOC059::chunk::1; DOC014::chunk::33; DOC035::chunk::6 | J17: none | K17: 363 | L17: 34.476 | M17: 1936 | N17: 543 | O17: 0 | P17: 2 | Q17: 2 | R17: 2 | S17: 1 | T17: 2 | U17: 2 | V17: 1 | W17: 21 | X17: =IF(COUNT(P17:V17)=0,"",SUM(P17:V17)) -> 12 | Y17: =IF(X17="","",X17/21) -> 0.57142857 | Z17: No made-up laws. Says the sources can't answer it, but to much fluff | AA17: The existing scientific evidence on atmospheric microplastics suggests that they are a global environmental issue contaminating aquatic and terrestrial environments [DOC035::chunk::2]. Microplastics have been reported in atmospheric deposition, indoor and outdoor air, raising concern for public health due to the potential for exposure [DOC035::chunk::2]. A study in central London found microplastics in all samples, with deposition rates ranging from 575 to 1008 microplastics/m^2/d [DOC035::chunk::2]. The microplastics were found in various shapes, with fibrous microplastics accounting for the great majority (92%) [DOC035::chunk::2]. The UK Earth System Model (UKESM1.1) has been used to simulate the transport and deposition of airborne microplastics [DOC059::chunk::1]. The model suggests that microplastics are present throughout the troposphere and can be transported into remote regions, including Antarctica [DOC059::chunk::1]. The model also suggests that dry deposition is the dominant microplastic removal pathway, but greater wet deposition occurs for smaller hydrophilic microplastics [DOC059::chunk::1]. The scientific evidence on microplastics is still limited, and there is a need for further research to understand the quantities, characteristics, and pathways of airborne microplastics [DOC035::chunk::2]. The current study aims to contribute to the limited existing knowledge by examining whether microplastics are present in total (wet and dry) atmospheric deposition in a megacity environment, London (UK) [DOC035::chunk::6]. In terms of policy instruments, the report "A Scientific Perspective on Microplastics in Nature and Society" (SAPEA Evidence Review Report No. 4) [DOC014::chunk::240] provides an overview of the existing natural sciences reviews and overview reports covering exposure, (eco)toxicology, environmental and human health risks, incorporating the most recent primary literature not covered by existing reviews. The report also reviews what has been learned from current computer modelling performed on the topic [DOC014::chunk::33]. However, the report does not specifically address UK policy instruments that address microplastics or cover atmospheric sources. The report aims to provide a rapid evidence review and summary of the existing natural sciences reviews and overview reports, but it does not provide a comprehensive overview of UK policy instruments [DOC014::chunk::33]. Therefore, it is not possible to determine what existing UK policy instruments address microplastics or cover atmospheric sources based on the provided sources. Further research is needed to understand the existing policy instruments and their coverage of microplastics and atmospheric sources. | AB17: 0 (local model) | AC17: f70bf13f-7cbe-4508-be69-6a2399b877ed
... A20: Q15 | B20: Evidence strength & uncertainty | C20: Hard | D20: Ecological impacts | E20: How strong is the evidence that atmospheric microplastic deposition has a detrimental ecological impact, and what evidence gaps limit policy action? | F20: DOC027 (wetland deposition), DOC050, 062 (deposition measurement) DOC049 (ecological risks) DOC036 (environmental fate and impacts) DOC103 (soil properties), DOC104 (soil carbon cycling. DOC026 (lettuce stress response), DOC105 (meta-analysis of known and unknown effects). | G20: bothe deposistona nd the effectson are both disgiussed and measured in the coupus however there isnt a study that recectaly links and compairs them | H20: well written and distuagised the differtnce from field observations and and lab stuidies. | I20: DOC035::chunk::36; DOC005::chunk::42; DOC014::chunk::241; DOC005::chunk::38; DOC014::chunk::9; DOC027::chunk::4 | J20: none | K20: 292 | L20: 26.184 | M20: 1796 | N20: 400 | O20: 0 | P20: 2 | Q20: 2 | R20: 2 | S20: 1 | T20: 2 | U20: 2 | V20: 1 | W20: 21 | X20: =IF(COUNT(P20:V20)=0,"",SUM(P20:V20)) -> 12 | Y20: =IF(X20="","",X20/21) -> 0.57142857 | Z20: Good figures. Doesn't separate lab studies from real world observations. | AA20: The evidence suggests that atmospheric microplastic deposition has a detrimental ecological impact. Studies have found microplastics in every sample collected in urban London, with average deposition rates greater than previously reported [DOC035::chunk::36]. This indicates that cities are a source of airborne microplastics to the wider environment. The deposition rates may increase to 100 mg/m²/year by 2050, raising concerns about the impact on human health, wildland soils, and waters [DOC005::chunk::42]. The inhalation of particles can be irritating to lung tissue and lead to serious diseases, and microplastics may even have the potential to accumulate in plants [DOC005::chunk::42]. However, the evidence is not yet conclusive about the ecological risks of atmospheric microplastic deposition. The SAPEA working group has concluded that there is a need for improved quality of methods and international harmonisation of measurement and assessment methods [DOC014::chunk::241]. They also noted that little is known about the ecological and human health risks of NMPs, and what is known is surrounded by considerable uncertainty [DOC014::chunk::241]. The working group has formulated three conclusions with respect to ecological risks, but these are based on limited evidence and require further research. The evidence gaps limit policy action in several areas. Firstly, there is a need for more knowledge about the dynamics of atmospheric microplastic dispersion and fate [DOC035::chunk::36]. Secondly, the effects of microplastics on biota and humans are not well understood, and more research is needed to clarify the risks [DOC014::chunk::241]. Finally, the working group has highlighted the need for improved plastic waste management and the removal of ocean plastics from the system [DOC005::chunk::42]. In conclusion, while the evidence suggests that atmospheric microplastic deposition has a detrimental ecological impact, the evidence is not yet conclusive, and further research is needed to clarify the risks and inform policy action. | AB20: 0 (local model) | AC20: 44ace286-c84f-4b45-aecf-b93202488591
A21: Q16 | B21: Evidence strength & uncertainty | C21: Hard | D21: Transport | E21: Is there evidence that atmospheric microplastic concentrations are increasing? | H21: should keep the solid conclusions apart from the bits where the scale or the mechanism is still uncertain. | I21: DOC035::chunk::6; DOC093::chunk::4; DOC016::chunk::214; DOC059::chunk::60; DOC003::chunk::71; DOC016::chunk::69 | J21: none | K21: 343 | L21: 31.03 | M21: 1870 | N21: 482 | O21: 0 | P21: 2 | Q21: 1 | R21: 2 | S21: 1 | T21: 2 | U21: 1 | V21: 1 | W21: 21 | X21: =IF(COUNT(P21:V21)=0,"",SUM(P21:V21)) -> 10 | Y21: =IF(X21="","",X21/21) -> 0.47619048 | Z21: reats predicted plastic growth as proof levels are rising. | AA21: The available evidence suggests that atmospheric microplastic concentrations are likely to increase in the future. According to [DOC059::chunk::60], global plastic production is projected to increase substantially over the coming decades, which will lead to a growth in microplastic emissions and their contribution to total atmospheric aerosol concentrations. This is particularly relevant in regions influenced by strong sources of microplastics, such as population centres. However, there is limited information on the current levels of atmospheric microplastic concentrations. [DOC035::chunk::6] notes that the transport of urban atmospheric microplastics is unknown, but a likely pathway to pristine environments. [DOC093::chunk::4] states that atmospheric transport has been identified as one of the major conveyors of microplastics in urban areas, but does not provide information on the magnitude of this transport. There is some evidence that microplastic concentrations in urban areas are higher than in remote locations, but the extent of this phenomenon is not well understood [DOC035::chunk::6]. [DOC003::chunk::71] notes that microplastic concentrations in ambient air have been shown to vary over months, suggesting temporal and seasonal variability. Overall, while there is some evidence that atmospheric microplastic concentrations are increasing, the available information is limited and more research is needed to fully understand the magnitude and implications of this trend. Scientific evidence: * Atmospheric microplastic transport is a likely pathway to pristine environments [DOC035::chunk::6]. * Atmospheric transport has been identified as one of the major conveyors of microplastics in urban areas [DOC093::chunk::4]. * Global plastic production is projected to increase substantially over the coming decades, leading to a growth in microplastic emissions [DOC059::chunk::60]. * Microplastic concentrations in urban areas are higher than in remote locations [DOC035::chunk::6]. * Microplastic concentrations in ambient air have been shown to vary over months, suggesting temporal and seasonal variability [DOC003::chunk::71]. Possible policy implications: * Further research is needed to fully understand the magnitude and implications of atmospheric microplastic concentrations. * Policies aimed at reducing plastic production and waste may be necessary to mitigate the growth of microplastic emissions. * Monitoring systems should be developed to assess the atmospheric deposition of microplastics in urban areas [DOC093::chunk::4]. | AB21: 0 (local model) | AC21: a9ad289f-77b3-43be-907e-3550dd778953
A22: Q17 | B22: Insufficient / out-of-scope | C22: Medium | D22: Sources / prioritisation | E22: Does the evidence allow one atmospheric microplastic source to be identified definitively as the highest priority for intervention? | G22: that there is no papers that ranks scoures of amps in tersm what waht is the main cuse. And stiddies state that there is an increase in certain areas but there isnt an exasutuve comparitve review | H22: says no and explains estimates disagree so ranking sources instead of just picking one. | I22: DOC014::chunk::259; DOC055::chunk::114; DOC030::chunk::50; DOC070::chunk::32; DOC022::chunk::356; DOC030::chunk::10 | J22: none | K22: 226 | L22: 25.507 | M22: 2343 | N22: 335 | O22: 0 | P22: 2 | Q22: 2 | R22: 1 | S22: n/a | T22: n/a | U22: 2 | V22: 1 | W22: 15 | X22: =IF(COUNT(P22:V22)=0,"",SUM(P22:V22)) -> 8 | Y22: =IF(X22="","",X22/15) -> 0.53333333 | Z22: Says no, but never explains why the estimates are too mixed to clearly give rankings to | AA22: The evidence suggests that atmospheric microplastics are a complex issue, and their sources are numerous and variable. According to Evangeliou et al. (2020) [DOC055::chunk::114], atmospheric transport is a major pathway of microplastics to remote regions. However, the exact sources of atmospheric microplastics are not well-defined, and more research is needed to understand their origin and abundance [DOC030::chunk::50]. The literature review by Evangeliou et al. (2020) [DOC055::chunk::114] identified areas with high population density as hotspots for atmospheric microplastics. However, studies in remote areas, such as the Pyrenees, the Alps, the Arctic, and protected areas of the western USA, have also been conducted [DOC030::chunk::10]. The evidence does not allow one atmospheric microplastic source to be identified definitively as the highest priority for intervention. The complex nature of atmospheric microplastics, with multiple sources and pathways, suggests that a comprehensive approach is needed to address this issue. Scientific evidence suggests that better methods in natural sciences alone will not solve the problem of atmospheric microplastics [DOC014::chunk::259]. Interdisciplinary collaboration between natural, technical, social, and behavioural sciences is necessary to address the complex issue of plastic waste and pollution [DOC014::chunk::259]. Possible policy implications include the need for a comprehensive approach to address the complex issue of atmospheric microplastics, including the development of standardized methods for exposure and hazard characterization, and the promotion of interdisciplinary collaboration between natural, technical, social, and behavioural sciences. | AB22: 0 (local model) | AC22: 7db12f38-0ebf-40d7-a4cb-1dd540a22637
